[E 171122 19:25:30 torndb:103] Cannot connect to MySQL on 10.10.10.135
    Traceback (most recent call last):
      File "/home/lianch/.local/lib/python2.7/site-packages/torndb.py", line 100, in __init__
        self.reconnect()
      File "/home/lianch/.local/lib/python2.7/site-packages/torndb.py", line 117, in reconnect
        self._db = MySQLdb.connect(**self._db_args)
      File "/home/lianch/.local/lib/python2.7/site-packages/MySQLdb/__init__.py", line 81, in Connect
        return Connection(*args, **kwargs)
      File "/home/lianch/.local/lib/python2.7/site-packages/MySQLdb/connections.py", line 193, in __init__
        super(Connection, self).__init__(*args, **kwargs2)
    OperationalError: (1049, "Unknown database 'ihome'")
[E 171122 19:26:15 torndb:103] Cannot connect to MySQL on 10.10.10.135
    Traceback (most recent call last):
      File "/home/lianch/.local/lib/python2.7/site-packages/torndb.py", line 100, in __init__
        self.reconnect()
      File "/home/lianch/.local/lib/python2.7/site-packages/torndb.py", line 117, in reconnect
        self._db = MySQLdb.connect(**self._db_args)
      File "/home/lianch/.local/lib/python2.7/site-packages/MySQLdb/__init__.py", line 81, in Connect
        return Connection(*args, **kwargs)
      File "/home/lianch/.local/lib/python2.7/site-packages/MySQLdb/connections.py", line 193, in __init__
        super(Connection, self).__init__(*args, **kwargs2)
    OperationalError: (1049, "Unknown database 'ihome'")
[E 171122 19:26:37 torndb:103] Cannot connect to MySQL on 10.10.10.135
    Traceback (most recent call last):
      File "/home/lianch/.local/lib/python2.7/site-packages/torndb.py", line 100, in __init__
        self.reconnect()
      File "/home/lianch/.local/lib/python2.7/site-packages/torndb.py", line 117, in reconnect
        self._db = MySQLdb.connect(**self._db_args)
      File "/home/lianch/.local/lib/python2.7/site-packages/MySQLdb/__init__.py", line 81, in Connect
        return Connection(*args, **kwargs)
      File "/home/lianch/.local/lib/python2.7/site-packages/MySQLdb/connections.py", line 193, in __init__
        super(Connection, self).__init__(*args, **kwargs2)
    OperationalError: (1049, "Unknown database 'ihome'")
[I 171122 19:32:32 web:2063] 200 GET /static/css/reset.css (127.0.0.1) 4.50ms
[W 171122 19:32:32 web:2063] 404 GET /api/check_login (127.0.0.1) 5.62ms
[W 171122 19:32:32 web:2063] 404 GET /api/house/index (127.0.0.1) 1.28ms
[W 171122 19:32:33 web:2063] 404 GET /api/check_login (127.0.0.1) 1.21ms
[W 171122 19:32:33 web:2063] 404 GET /api/house/index (127.0.0.1) 1.78ms
[I 171122 22:03:36 autoreload:198] server.py modified; restarting server
[E 171122 22:03:36 torndb:103] Cannot connect to MySQL on 10.10.10.135
    Traceback (most recent call last):
      File "/home/lianch/.local/lib/python2.7/site-packages/torndb.py", line 100, in __init__
        self.reconnect()
      File "/home/lianch/.local/lib/python2.7/site-packages/torndb.py", line 117, in reconnect
        self._db = MySQLdb.connect(**self._db_args)
      File "/home/lianch/.local/lib/python2.7/site-packages/MySQLdb/__init__.py", line 81, in Connect
        return Connection(*args, **kwargs)
      File "/home/lianch/.local/lib/python2.7/site-packages/MySQLdb/connections.py", line 193, in __init__
        super(Connection, self).__init__(*args, **kwargs2)
    OperationalError: (1049, "Unknown database 'ihome'")
[I 171122 22:08:16 autoreload:198] server.py modified; restarting server
[E 171122 22:08:16 torndb:103] Cannot connect to MySQL on 10.10.10.135
    Traceback (most recent call last):
      File "/home/lianch/.local/lib/python2.7/site-packages/torndb.py", line 100, in __init__
        self.reconnect()
      File "/home/lianch/.local/lib/python2.7/site-packages/torndb.py", line 117, in reconnect
        self._db = MySQLdb.connect(**self._db_args)
      File "/home/lianch/.local/lib/python2.7/site-packages/MySQLdb/__init__.py", line 81, in Connect
        return Connection(*args, **kwargs)
      File "/home/lianch/.local/lib/python2.7/site-packages/MySQLdb/connections.py", line 193, in __init__
        super(Connection, self).__init__(*args, **kwargs2)
    OperationalError: (1049, "Unknown database 'ihome'")
[I 171122 22:08:55 autoreload:198] server.py modified; restarting server
[E 171122 22:08:55 torndb:103] Cannot connect to MySQL on 10.10.10.135
    Traceback (most recent call last):
      File "/home/lianch/.local/lib/python2.7/site-packages/torndb.py", line 100, in __init__
        self.reconnect()
      File "/home/lianch/.local/lib/python2.7/site-packages/torndb.py", line 117, in reconnect
        self._db = MySQLdb.connect(**self._db_args)
      File "/home/lianch/.local/lib/python2.7/site-packages/MySQLdb/__init__.py", line 81, in Connect
        return Connection(*args, **kwargs)
      File "/home/lianch/.local/lib/python2.7/site-packages/MySQLdb/connections.py", line 193, in __init__
        super(Connection, self).__init__(*args, **kwargs2)
    OperationalError: (1049, "Unknown database 'ihome'")
[I 171122 22:12:56 autoreload:198] server.py modified; restarting server
[E 171122 22:12:56 torndb:103] Cannot connect to MySQL on 10.10.10.135
    Traceback (most recent call last):
      File "/home/lianch/.local/lib/python2.7/site-packages/torndb.py", line 100, in __init__
        self.reconnect()
      File "/home/lianch/.local/lib/python2.7/site-packages/torndb.py", line 117, in reconnect
        self._db = MySQLdb.connect(**self._db_args)
      File "/home/lianch/.local/lib/python2.7/site-packages/MySQLdb/__init__.py", line 81, in Connect
        return Connection(*args, **kwargs)
      File "/home/lianch/.local/lib/python2.7/site-packages/MySQLdb/connections.py", line 193, in __init__
        super(Connection, self).__init__(*args, **kwargs2)
    OperationalError: (1049, "Unknown database 'ihome'")
[I 171122 22:18:13 autoreload:198] server.py modified; restarting server
[E 171122 22:18:13 torndb:103] Cannot connect to MySQL on 10.10.10.135
    Traceback (most recent call last):
      File "/home/lianch/.local/lib/python2.7/site-packages/torndb.py", line 100, in __init__
        self.reconnect()
      File "/home/lianch/.local/lib/python2.7/site-packages/torndb.py", line 117, in reconnect
        self._db = MySQLdb.connect(**self._db_args)
      File "/home/lianch/.local/lib/python2.7/site-packages/MySQLdb/__init__.py", line 81, in Connect
        return Connection(*args, **kwargs)
      File "/home/lianch/.local/lib/python2.7/site-packages/MySQLdb/connections.py", line 193, in __init__
        super(Connection, self).__init__(*args, **kwargs2)
    OperationalError: (1049, "Unknown database 'ihome'")
[E 171122 23:18:16 torndb:103] Cannot connect to MySQL on 10.10.10.135
    Traceback (most recent call last):
      File "/home/lianch/.local/lib/python2.7/site-packages/torndb.py", line 100, in __init__
        self.reconnect()
      File "/home/lianch/.local/lib/python2.7/site-packages/torndb.py", line 117, in reconnect
        self._db = MySQLdb.connect(**self._db_args)
      File "/home/lianch/.local/lib/python2.7/site-packages/MySQLdb/__init__.py", line 81, in Connect
        return Connection(*args, **kwargs)
      File "/home/lianch/.local/lib/python2.7/site-packages/MySQLdb/connections.py", line 193, in __init__
        super(Connection, self).__init__(*args, **kwargs2)
    OperationalError: (1049, "Unknown database 'ihome'")
[E 171122 23:20:07 torndb:103] Cannot connect to MySQL on 10.10.10.135
    Traceback (most recent call last):
      File "/home/lianch/.local/lib/python2.7/site-packages/torndb.py", line 100, in __init__
        self.reconnect()
      File "/home/lianch/.local/lib/python2.7/site-packages/torndb.py", line 117, in reconnect
        self._db = MySQLdb.connect(**self._db_args)
      File "/home/lianch/.local/lib/python2.7/site-packages/MySQLdb/__init__.py", line 81, in Connect
        return Connection(*args, **kwargs)
      File "/home/lianch/.local/lib/python2.7/site-packages/MySQLdb/connections.py", line 193, in __init__
        super(Connection, self).__init__(*args, **kwargs2)
    OperationalError: (1049, "Unknown database 'ihome'")
[E 171122 23:22:28 torndb:103] Cannot connect to MySQL on 10.10.10.135
    Traceback (most recent call last):
      File "/home/lianch/.local/lib/python2.7/site-packages/torndb.py", line 100, in __init__
        self.reconnect()
      File "/home/lianch/.local/lib/python2.7/site-packages/torndb.py", line 117, in reconnect
        self._db = MySQLdb.connect(**self._db_args)
      File "/home/lianch/.local/lib/python2.7/site-packages/MySQLdb/__init__.py", line 81, in Connect
        return Connection(*args, **kwargs)
      File "/home/lianch/.local/lib/python2.7/site-packages/MySQLdb/connections.py", line 193, in __init__
        super(Connection, self).__init__(*args, **kwargs2)
    OperationalError: (1049, "Unknown database 'ihome'")
[I 171122 23:22:34 web:2063] 304 GET / (127.0.0.1) 17.67ms
[I 171122 23:22:34 web:2063] 304 GET /static/plugins/bootstrap/css/bootstrap.min.css (127.0.0.1) 49.98ms
[I 171122 23:22:34 web:2063] 304 GET /static/plugins/font-awesome/css/font-awesome.min.css (127.0.0.1) 16.94ms
[I 171122 23:22:34 web:2063] 304 GET /static/css/reset.css (127.0.0.1) 3.35ms
[I 171122 23:22:34 web:2063] 304 GET /static/plugins/swiper/css/swiper.min.css (127.0.0.1) 15.18ms
[I 171122 23:22:34 web:2063] 304 GET /static/plugins/bootstrap-datepicker/css/bootstrap-datepicker.min.css (127.0.0.1) 4.36ms
[I 171122 23:22:34 web:2063] 304 GET /static/css/ihome/main.css (127.0.0.1) 3.67ms
[I 171122 23:22:34 web:2063] 304 GET /static/css/ihome/index.css (127.0.0.1) 3.28ms
[I 171122 23:22:34 web:2063] 304 GET /static/js/jquery.min.js (127.0.0.1) 3.83ms
[I 171122 23:22:34 web:2063] 304 GET /static/plugins/bootstrap/js/bootstrap.min.js (127.0.0.1) 12.61ms
[I 171122 23:22:34 web:2063] 304 GET /static/plugins/font-awesome/fonts/fontawesome-webfont.woff2?v=4.6.3 (127.0.0.1) 6.87ms
[I 171122 23:22:34 web:2063] 304 GET /static/js/template.js (127.0.0.1) 1.16ms
[I 171122 23:22:34 web:2063] 304 GET /static/plugins/bootstrap-datepicker/locales/bootstrap-datepicker.zh-CN.min.js (127.0.0.1) 0.96ms
[I 171122 23:22:34 web:2063] 304 GET /static/plugins/bootstrap-datepicker/js/bootstrap-datepicker.min.js (127.0.0.1) 4.67ms
[I 171122 23:22:34 web:2063] 304 GET /static/plugins/swiper/js/swiper.jquery.min.js (127.0.0.1) 1.52ms
[I 171122 23:22:34 web:2063] 304 GET /static/images/logo@128x59.png (127.0.0.1) 1.15ms
[I 171122 23:22:34 web:2063] 304 GET /static/js/ihome/index.js (127.0.0.1) 2.73ms
[W 171122 23:22:34 web:2063] 404 GET /api/check_login (127.0.0.1) 2.75ms
[W 171122 23:22:34 web:2063] 404 GET /api/house/index (127.0.0.1) 1.08ms
[I 171122 23:22:34 web:2063] 200 GET /favicon.ico (127.0.0.1) 0.72ms
[I 171122 23:22:40 web:2063] 200 GET /login.html (127.0.0.1) 15.97ms
[I 171122 23:22:40 web:2063] 200 GET /static/css/ihome/login.css (127.0.0.1) 1.58ms
[I 171122 23:22:40 web:2063] 200 GET /static/js/ihome/login.js (127.0.0.1) 2.78ms
[W 171122 23:22:49 web:2063] 404 GET /login (127.0.0.1) 1.86ms
[E 171123 12:04:18 torndb:103] Cannot connect to MySQL on 10.10.10.135
    Traceback (most recent call last):
      File "/home/lianch/.local/lib/python2.7/site-packages/torndb.py", line 100, in __init__
        self.reconnect()
      File "/home/lianch/.local/lib/python2.7/site-packages/torndb.py", line 117, in reconnect
        self._db = MySQLdb.connect(**self._db_args)
      File "/home/lianch/.local/lib/python2.7/site-packages/MySQLdb/__init__.py", line 81, in Connect
        return Connection(*args, **kwargs)
      File "/home/lianch/.local/lib/python2.7/site-packages/MySQLdb/connections.py", line 193, in __init__
        super(Connection, self).__init__(*args, **kwargs2)
    OperationalError: (1049, "Unknown database 'ihome'")
[E 171124 15:24:46 torndb:103] Cannot connect to MySQL on 10.10.10.135
    Traceback (most recent call last):
      File "/home/lianch/.local/lib/python2.7/site-packages/torndb.py", line 100, in __init__
        self.reconnect()
      File "/home/lianch/.local/lib/python2.7/site-packages/torndb.py", line 117, in reconnect
        self._db = MySQLdb.connect(**self._db_args)
      File "/home/lianch/.local/lib/python2.7/site-packages/MySQLdb/__init__.py", line 81, in Connect
        return Connection(*args, **kwargs)
      File "/home/lianch/.local/lib/python2.7/site-packages/MySQLdb/connections.py", line 193, in __init__
        super(Connection, self).__init__(*args, **kwargs2)
    OperationalError: (1049, "Unknown database 'ihome'")
[I 171124 15:24:53 web:2063] 200 GET / (127.0.0.1) 159.47ms
[I 171124 15:24:53 web:2063] 304 GET /static/plugins/swiper/css/swiper.min.css (127.0.0.1) 50.71ms
[I 171124 15:24:53 web:2063] 304 GET /static/plugins/bootstrap-datepicker/css/bootstrap-datepicker.min.css (127.0.0.1) 8.84ms
[I 171124 15:24:53 web:2063] 304 GET /static/css/ihome/index.css (127.0.0.1) 10.94ms
[I 171124 15:24:53 web:2063] 304 GET /static/js/jquery.min.js (127.0.0.1) 39.30ms
[I 171124 15:24:53 web:2063] 304 GET /static/plugins/bootstrap/css/bootstrap.min.css (127.0.0.1) 57.48ms
[I 171124 15:24:53 web:2063] 304 GET /static/css/ihome/main.css (127.0.0.1) 7.72ms
[I 171124 15:24:53 web:2063] 200 GET /static/css/reset.css (127.0.0.1) 5.40ms
[I 171124 15:24:53 web:2063] 304 GET /static/plugins/font-awesome/css/font-awesome.min.css (127.0.0.1) 8.06ms
[I 171124 15:24:53 web:2063] 304 GET /static/plugins/bootstrap-datepicker/js/bootstrap-datepicker.min.js (127.0.0.1) 22.86ms
[I 171124 15:24:53 web:2063] 304 GET /static/plugins/bootstrap/js/bootstrap.min.js (127.0.0.1) 5.02ms
[I 171124 15:24:53 web:2063] 304 GET /static/js/template.js (127.0.0.1) 11.06ms
[I 171124 15:24:53 web:2063] 304 GET /static/js/ihome/index.js (127.0.0.1) 12.78ms
[I 171124 15:24:53 web:2063] 304 GET /static/plugins/bootstrap-datepicker/locales/bootstrap-datepicker.zh-CN.min.js (127.0.0.1) 6.55ms
[I 171124 15:24:53 web:2063] 304 GET /static/plugins/swiper/js/swiper.jquery.min.js (127.0.0.1) 1.92ms
[I 171124 15:24:53 web:2063] 304 GET /static/images/logo@128x59.png (127.0.0.1) 17.47ms
[W 171124 15:24:53 web:2063] 404 GET /api/check_login (127.0.0.1) 11.02ms
[W 171124 15:24:53 web:2063] 404 GET /api/house/index (127.0.0.1) 3.48ms
[W 171124 15:24:57 web:2063] 404 GET /login (127.0.0.1) 3.68ms
[W 171124 15:25:07 web:2063] 404 GET /api/login (127.0.0.1) 8.12ms
[I 171124 15:28:33 web:2063] 304 GET /login.html (127.0.0.1) 61.07ms
[I 171124 15:28:33 web:2063] 304 GET /static/css/ihome/login.css (127.0.0.1) 13.20ms
[I 171124 15:28:33 web:2063] 304 GET /static/js/ihome/login.js (127.0.0.1) 51.78ms
[I 171124 15:30:12 autoreload:198] /home/lianch/myprojects/python/tornado_test/ihome/handlers/Passport.py modified; restarting server
[E 171124 15:30:13 torndb:103] Cannot connect to MySQL on 10.10.10.135
    Traceback (most recent call last):
      File "/home/lianch/.local/lib/python2.7/site-packages/torndb.py", line 100, in __init__
        self.reconnect()
      File "/home/lianch/.local/lib/python2.7/site-packages/torndb.py", line 117, in reconnect
        self._db = MySQLdb.connect(**self._db_args)
      File "/home/lianch/.local/lib/python2.7/site-packages/MySQLdb/__init__.py", line 81, in Connect
        return Connection(*args, **kwargs)
      File "/home/lianch/.local/lib/python2.7/site-packages/MySQLdb/connections.py", line 193, in __init__
        super(Connection, self).__init__(*args, **kwargs2)
    OperationalError: (1049, "Unknown database 'ihome'")
[E 171124 15:30:26 torndb:103] Cannot connect to MySQL on 10.10.10.135
    Traceback (most recent call last):
      File "/home/lianch/.local/lib/python2.7/site-packages/torndb.py", line 100, in __init__
        self.reconnect()
      File "/home/lianch/.local/lib/python2.7/site-packages/torndb.py", line 117, in reconnect
        self._db = MySQLdb.connect(**self._db_args)
      File "/home/lianch/.local/lib/python2.7/site-packages/MySQLdb/__init__.py", line 81, in Connect
        return Connection(*args, **kwargs)
      File "/home/lianch/.local/lib/python2.7/site-packages/MySQLdb/connections.py", line 193, in __init__
        super(Connection, self).__init__(*args, **kwargs2)
    OperationalError: (1049, "Unknown database 'ihome'")
[W 171124 15:30:38 web:1587] 403 POST /api/login (127.0.0.1): '_xsrf' argument missing from POST
[W 171124 15:30:38 web:2063] 403 POST /api/login (127.0.0.1) 2.50ms
[W 171124 15:30:51 web:1587] 403 POST /api/login (127.0.0.1): '_xsrf' argument missing from POST
[W 171124 15:30:51 web:2063] 403 POST /api/login (127.0.0.1) 1.20ms
[W 171124 15:31:58 web:1587] 403 POST /api/login (127.0.0.1): '_xsrf' argument missing from POST
[W 171124 15:31:58 web:2063] 403 POST /api/login (127.0.0.1) 1.14ms
[W 171124 15:32:24 web:1587] 403 POST /api/login (127.0.0.1): '_xsrf' argument missing from POST
[W 171124 15:32:24 web:2063] 403 POST /api/login (127.0.0.1) 0.85ms
[I 171124 15:35:34 autoreload:198] /home/lianch/myprojects/python/tornado_test/ihome/config.py modified; restarting server
[E 171124 15:35:34 torndb:103] Cannot connect to MySQL on 10.10.10.135
    Traceback (most recent call last):
      File "/home/lianch/.local/lib/python2.7/site-packages/torndb.py", line 100, in __init__
        self.reconnect()
      File "/home/lianch/.local/lib/python2.7/site-packages/torndb.py", line 117, in reconnect
        self._db = MySQLdb.connect(**self._db_args)
      File "/home/lianch/.local/lib/python2.7/site-packages/MySQLdb/__init__.py", line 81, in Connect
        return Connection(*args, **kwargs)
      File "/home/lianch/.local/lib/python2.7/site-packages/MySQLdb/connections.py", line 193, in __init__
        super(Connection, self).__init__(*args, **kwargs2)
    OperationalError: (1049, "Unknown database 'ihome'")
[E 171124 15:35:40 torndb:103] Cannot connect to MySQL on 10.10.10.135
    Traceback (most recent call last):
      File "/home/lianch/.local/lib/python2.7/site-packages/torndb.py", line 100, in __init__
        self.reconnect()
      File "/home/lianch/.local/lib/python2.7/site-packages/torndb.py", line 117, in reconnect
        self._db = MySQLdb.connect(**self._db_args)
      File "/home/lianch/.local/lib/python2.7/site-packages/MySQLdb/__init__.py", line 81, in Connect
        return Connection(*args, **kwargs)
      File "/home/lianch/.local/lib/python2.7/site-packages/MySQLdb/connections.py", line 193, in __init__
        super(Connection, self).__init__(*args, **kwargs2)
    OperationalError: (1049, "Unknown database 'ihome'")
[W 171124 15:35:58 web:2063] 405 POST /api/login (127.0.0.1) 1.41ms
[W 171124 15:36:11 web:2063] 405 POST /api/login (127.0.0.1) 0.85ms
[I 171124 15:38:20 autoreload:198] /home/lianch/myprojects/python/tornado_test/ihome/config.py modified; restarting server
[E 171124 15:38:20 torndb:103] Cannot connect to MySQL on 10.10.10.135
    Traceback (most recent call last):
      File "/home/lianch/.local/lib/python2.7/site-packages/torndb.py", line 100, in __init__
        self.reconnect()
      File "/home/lianch/.local/lib/python2.7/site-packages/torndb.py", line 117, in reconnect
        self._db = MySQLdb.connect(**self._db_args)
      File "/home/lianch/.local/lib/python2.7/site-packages/MySQLdb/__init__.py", line 81, in Connect
        return Connection(*args, **kwargs)
      File "/home/lianch/.local/lib/python2.7/site-packages/MySQLdb/connections.py", line 193, in __init__
        super(Connection, self).__init__(*args, **kwargs2)
    OperationalError: (1049, "Unknown database 'ihome'")
[E 171124 15:38:25 torndb:103] Cannot connect to MySQL on 10.10.10.135
    Traceback (most recent call last):
      File "/home/lianch/.local/lib/python2.7/site-packages/torndb.py", line 100, in __init__
        self.reconnect()
      File "/home/lianch/.local/lib/python2.7/site-packages/torndb.py", line 117, in reconnect
        self._db = MySQLdb.connect(**self._db_args)
      File "/home/lianch/.local/lib/python2.7/site-packages/MySQLdb/__init__.py", line 81, in Connect
        return Connection(*args, **kwargs)
      File "/home/lianch/.local/lib/python2.7/site-packages/MySQLdb/connections.py", line 193, in __init__
        super(Connection, self).__init__(*args, **kwargs2)
    OperationalError: (1049, "Unknown database 'ihome'")
[E 171124 15:38:57 torndb:103] Cannot connect to MySQL on 10.10.10.135
    Traceback (most recent call last):
      File "/home/lianch/.local/lib/python2.7/site-packages/torndb.py", line 100, in __init__
        self.reconnect()
      File "/home/lianch/.local/lib/python2.7/site-packages/torndb.py", line 117, in reconnect
        self._db = MySQLdb.connect(**self._db_args)
      File "/home/lianch/.local/lib/python2.7/site-packages/MySQLdb/__init__.py", line 81, in Connect
        return Connection(*args, **kwargs)
      File "/home/lianch/.local/lib/python2.7/site-packages/MySQLdb/connections.py", line 193, in __init__
        super(Connection, self).__init__(*args, **kwargs2)
    OperationalError: (1049, "Unknown database 'ihome'")
[I 171124 15:40:03 autoreload:198] /home/lianch/myprojects/python/tornado_test/ihome/handlers/Passport.py modified; restarting server
[E 171124 15:40:03 torndb:103] Cannot connect to MySQL on 10.10.10.135
    Traceback (most recent call last):
      File "/home/lianch/.local/lib/python2.7/site-packages/torndb.py", line 100, in __init__
        self.reconnect()
      File "/home/lianch/.local/lib/python2.7/site-packages/torndb.py", line 117, in reconnect
        self._db = MySQLdb.connect(**self._db_args)
      File "/home/lianch/.local/lib/python2.7/site-packages/MySQLdb/__init__.py", line 81, in Connect
        return Connection(*args, **kwargs)
      File "/home/lianch/.local/lib/python2.7/site-packages/MySQLdb/connections.py", line 193, in __init__
        super(Connection, self).__init__(*args, **kwargs2)
    OperationalError: (1049, "Unknown database 'ihome'")
[E 171124 15:40:07 torndb:103] Cannot connect to MySQL on 10.10.10.135
    Traceback (most recent call last):
      File "/home/lianch/.local/lib/python2.7/site-packages/torndb.py", line 100, in __init__
        self.reconnect()
      File "/home/lianch/.local/lib/python2.7/site-packages/torndb.py", line 117, in reconnect
        self._db = MySQLdb.connect(**self._db_args)
      File "/home/lianch/.local/lib/python2.7/site-packages/MySQLdb/__init__.py", line 81, in Connect
        return Connection(*args, **kwargs)
      File "/home/lianch/.local/lib/python2.7/site-packages/MySQLdb/connections.py", line 193, in __init__
        super(Connection, self).__init__(*args, **kwargs2)
    OperationalError: (1049, "Unknown database 'ihome'")
[W 171124 15:40:10 web:2063] 405 POST /api/login (127.0.0.1) 2.15ms
[W 171124 15:40:12 web:2063] 405 POST /api/login (127.0.0.1) 0.82ms
[I 171124 15:43:04 autoreload:198] /home/lianch/myprojects/python/tornado_test/ihome/handlers/BaseHandler.py modified; restarting server
[E 171124 15:43:04 torndb:103] Cannot connect to MySQL on 10.10.10.135
    Traceback (most recent call last):
      File "/home/lianch/.local/lib/python2.7/site-packages/torndb.py", line 100, in __init__
        self.reconnect()
      File "/home/lianch/.local/lib/python2.7/site-packages/torndb.py", line 117, in reconnect
        self._db = MySQLdb.connect(**self._db_args)
      File "/home/lianch/.local/lib/python2.7/site-packages/MySQLdb/__init__.py", line 81, in Connect
        return Connection(*args, **kwargs)
      File "/home/lianch/.local/lib/python2.7/site-packages/MySQLdb/connections.py", line 193, in __init__
        super(Connection, self).__init__(*args, **kwargs2)
    OperationalError: (1049, "Unknown database 'ihome'")
[E 171124 15:43:07 torndb:103] Cannot connect to MySQL on 10.10.10.135
    Traceback (most recent call last):
      File "/home/lianch/.local/lib/python2.7/site-packages/torndb.py", line 100, in __init__
        self.reconnect()
      File "/home/lianch/.local/lib/python2.7/site-packages/torndb.py", line 117, in reconnect
        self._db = MySQLdb.connect(**self._db_args)
      File "/home/lianch/.local/lib/python2.7/site-packages/MySQLdb/__init__.py", line 81, in Connect
        return Connection(*args, **kwargs)
      File "/home/lianch/.local/lib/python2.7/site-packages/MySQLdb/connections.py", line 193, in __init__
        super(Connection, self).__init__(*args, **kwargs2)
    OperationalError: (1049, "Unknown database 'ihome'")
[W 171124 15:43:14 web:2063] 405 POST /api/login (127.0.0.1) 1.81ms
[W 171124 15:43:20 web:2063] 405 POST /api/login (127.0.0.1) 0.82ms
[W 171124 15:43:41 web:2063] 405 POST /api/login (127.0.0.1) 1.06ms
[W 171124 15:43:41 web:2063] 405 POST /api/login (127.0.0.1) 1.01ms
[I 171124 15:44:57 autoreload:198] /home/lianch/myprojects/python/tornado_test/ihome/handlers/BaseHandler.py modified; restarting server
[E 171124 15:44:58 torndb:103] Cannot connect to MySQL on 10.10.10.135
    Traceback (most recent call last):
      File "/home/lianch/.local/lib/python2.7/site-packages/torndb.py", line 100, in __init__
        self.reconnect()
      File "/home/lianch/.local/lib/python2.7/site-packages/torndb.py", line 117, in reconnect
        self._db = MySQLdb.connect(**self._db_args)
      File "/home/lianch/.local/lib/python2.7/site-packages/MySQLdb/__init__.py", line 81, in Connect
        return Connection(*args, **kwargs)
      File "/home/lianch/.local/lib/python2.7/site-packages/MySQLdb/connections.py", line 193, in __init__
        super(Connection, self).__init__(*args, **kwargs2)
    OperationalError: (1049, "Unknown database 'ihome'")
[E 171124 15:45:01 torndb:103] Cannot connect to MySQL on 10.10.10.135
    Traceback (most recent call last):
      File "/home/lianch/.local/lib/python2.7/site-packages/torndb.py", line 100, in __init__
        self.reconnect()
      File "/home/lianch/.local/lib/python2.7/site-packages/torndb.py", line 117, in reconnect
        self._db = MySQLdb.connect(**self._db_args)
      File "/home/lianch/.local/lib/python2.7/site-packages/MySQLdb/__init__.py", line 81, in Connect
        return Connection(*args, **kwargs)
      File "/home/lianch/.local/lib/python2.7/site-packages/MySQLdb/connections.py", line 193, in __init__
        super(Connection, self).__init__(*args, **kwargs2)
    OperationalError: (1049, "Unknown database 'ihome'")
[W 171124 15:45:14 web:2063] 405 POST /api/login (127.0.0.1) 1.72ms
[W 171124 15:45:16 web:2063] 405 POST /api/login (127.0.0.1) 0.60ms
[W 171124 15:45:17 web:2063] 405 POST /api/login (127.0.0.1) 0.93ms
[I 171124 15:46:31 autoreload:198] server.py modified; restarting server
[E 171124 15:47:07 server:42] connect db
[E 171124 15:47:07 torndb:103] Cannot connect to MySQL on 10.10.10.135
    Traceback (most recent call last):
      File "/home/lianch/.local/lib/python2.7/site-packages/torndb.py", line 100, in __init__
        self.reconnect()
      File "/home/lianch/.local/lib/python2.7/site-packages/torndb.py", line 117, in reconnect
        self._db = MySQLdb.connect(**self._db_args)
      File "/home/lianch/.local/lib/python2.7/site-packages/MySQLdb/__init__.py", line 81, in Connect
        return Connection(*args, **kwargs)
      File "/home/lianch/.local/lib/python2.7/site-packages/MySQLdb/connections.py", line 193, in __init__
        super(Connection, self).__init__(*args, **kwargs2)
    OperationalError: (1049, "Unknown database 'ihome'")
[W 171124 15:47:12 web:2063] 405 POST /api/login (127.0.0.1) 1.33ms
[I 171124 15:47:38 autoreload:198] server.py modified; restarting server
[E 171124 15:47:38 server:43] connect db
[E 171124 15:47:38 torndb:103] Cannot connect to MySQL on 10.10.10.135
    Traceback (most recent call last):
      File "/home/lianch/.local/lib/python2.7/site-packages/torndb.py", line 100, in __init__
        self.reconnect()
      File "/home/lianch/.local/lib/python2.7/site-packages/torndb.py", line 117, in reconnect
        self._db = MySQLdb.connect(**self._db_args)
      File "/home/lianch/.local/lib/python2.7/site-packages/MySQLdb/__init__.py", line 81, in Connect
        return Connection(*args, **kwargs)
      File "/home/lianch/.local/lib/python2.7/site-packages/MySQLdb/connections.py", line 193, in __init__
        super(Connection, self).__init__(*args, **kwargs2)
    OperationalError: (1049, "Unknown database 'ihome'")
[E 171124 15:47:45 server:43] connect db
[E 171124 15:47:45 torndb:103] Cannot connect to MySQL on 10.10.10.135
    Traceback (most recent call last):
      File "/home/lianch/.local/lib/python2.7/site-packages/torndb.py", line 100, in __init__
        self.reconnect()
      File "/home/lianch/.local/lib/python2.7/site-packages/torndb.py", line 117, in reconnect
        self._db = MySQLdb.connect(**self._db_args)
      File "/home/lianch/.local/lib/python2.7/site-packages/MySQLdb/__init__.py", line 81, in Connect
        return Connection(*args, **kwargs)
      File "/home/lianch/.local/lib/python2.7/site-packages/MySQLdb/connections.py", line 193, in __init__
        super(Connection, self).__init__(*args, **kwargs2)
    OperationalError: (1049, "Unknown database 'ihome'")
[I 171124 15:48:37 autoreload:198] server.py modified; restarting server
[W 171124 15:48:49 web:2063] 405 POST /api/login (127.0.0.1) 1.35ms
[I 171124 15:50:39 autoreload:198] /home/lianch/myprojects/python/tornado_test/ihome/handlers/Passport.py modified; restarting server
[W 171124 15:50:52 web:2063] 404 GET /api/login (127.0.0.1) 23.02ms
[I 171124 15:51:45 autoreload:198] /home/lianch/myprojects/python/tornado_test/ihome/urls.py modified; restarting server
[I 171124 15:52:22 autoreload:198] /home/lianch/myprojects/python/tornado_test/ihome/urls.py modified; restarting server
[E 171124 15:52:36 BaseHandler:53] BaseHandler
[I 171124 15:52:36 web:2063] 200 GET /api/login (127.0.0.1) 2.63ms
[E 171124 15:52:45 BaseHandler:53] BaseHandler{
    'a':'hello',
    'b':'tornado'
    }
[E 171124 15:52:45 web:1590] Uncaught exception POST /api/login (127.0.0.1)
    HTTPServerRequest(protocol='http', host='127.0.0.1:8000', method='POST', uri='/api/login', version='HTTP/1.1', remote_ip='127.0.0.1', headers={'Content-Length': '30', 'Accept-Encoding': 'gzip, deflate', 'Connection': 'keep-alive', 'Accept': '*/*', 'User-Agent': 'PostmanRuntime/6.4.1', 'Host': '127.0.0.1:8000', 'Cookie': '_xsrf=2|f68f9254|41dd548a8fec66ca6cfaac5ebeed591b|1511509421', 'Cache-Control': 'no-cache', 'Content-Type': 'text/plain', 'Postman-Token': 'ae0d021e-c0ae-44ed-aaa3-55a672d9776b'})
    Traceback (most recent call last):
      File "/home/lianch/.local/lib/python2.7/site-packages/tornado/web.py", line 1509, in _execute
        result = method(*self.path_args, **self.path_kwargs)
      File "/home/lianch/myprojects/python/tornado_test/ihome/handlers/Passport.py", line 80, in post
        mobile = self.json_args('mobile')
    TypeError: 'dict' object is not callable
[E 171124 15:52:45 web:2063] 500 POST /api/login (127.0.0.1) 1.79ms
[I 171124 15:55:10 autoreload:198] /home/lianch/myprojects/python/tornado_test/ihome/urls.py modified; restarting server
[I 171124 15:55:31 autoreload:198] /home/lianch/myprojects/python/tornado_test/ihome/handlers/BaseHandler.py modified; restarting server
[I 171124 15:56:04 autoreload:198] /home/lianch/myprojects/python/tornado_test/ihome/handlers/Passport.py modified; restarting server
[E 171124 15:56:23 web:1590] Uncaught exception POST /api/login (127.0.0.1)
    HTTPServerRequest(protocol='http', host='127.0.0.1:8000', method='POST', uri='/api/login', version='HTTP/1.1', remote_ip='127.0.0.1', headers={'Content-Length': '30', 'Accept-Encoding': 'gzip, deflate', 'Connection': 'keep-alive', 'Accept': '*/*', 'User-Agent': 'PostmanRuntime/6.4.1', 'Host': '127.0.0.1:8000', 'Cookie': '_xsrf=2|f68f9254|41dd548a8fec66ca6cfaac5ebeed591b|1511509421', 'Cache-Control': 'no-cache', 'Content-Type': 'text/plain', 'Postman-Token': 'f12785e3-c581-408d-ae54-aa10aab1e7b5'})
    Traceback (most recent call last):
      File "/home/lianch/.local/lib/python2.7/site-packages/tornado/web.py", line 1509, in _execute
        result = method(*self.path_args, **self.path_kwargs)
      File "/home/lianch/myprojects/python/tornado_test/ihome/handlers/Passport.py", line 87, in post
        if not all((mobile,passwd)):
    UnboundLocalError: local variable 'passwd' referenced before assignment
[E 171124 15:56:23 web:2063] 500 POST /api/login (127.0.0.1) 1.87ms
[I 171124 16:03:06 autoreload:198] /home/lianch/myprojects/python/tornado_test/ihome/handlers/Passport.py modified; restarting server
[I 171124 16:03:11 Passport:82] info
[D 171124 16:03:11 Passport:83] debug
[W 171124 16:03:11 Passport:84] warnning
[E 171124 16:03:11 Passport:85] error
[E 171124 16:03:11 web:1590] Uncaught exception POST /api/login (127.0.0.1)
    HTTPServerRequest(protocol='http', host='127.0.0.1:8000', method='POST', uri='/api/login', version='HTTP/1.1', remote_ip='127.0.0.1', headers={'Content-Length': '30', 'Accept-Encoding': 'gzip, deflate', 'Connection': 'keep-alive', 'Accept': '*/*', 'User-Agent': 'PostmanRuntime/6.4.1', 'Host': '127.0.0.1:8000', 'Cookie': '_xsrf=2|f68f9254|41dd548a8fec66ca6cfaac5ebeed591b|1511509421', 'Cache-Control': 'no-cache', 'Content-Type': 'text/plain', 'Postman-Token': '2f54dc4a-de69-4d3f-9238-aeb40fc3cd5f'})
    Traceback (most recent call last):
      File "/home/lianch/.local/lib/python2.7/site-packages/tornado/web.py", line 1509, in _execute
        result = method(*self.path_args, **self.path_kwargs)
      File "/home/lianch/myprojects/python/tornado_test/ihome/handlers/Passport.py", line 88, in post
        if not all((mobile,passwd)):
    UnboundLocalError: local variable 'passwd' referenced before assignment
[E 171124 16:03:11 web:2063] 500 POST /api/login (127.0.0.1) 2.61ms
[I 171124 16:03:48 autoreload:198] /home/lianch/myprojects/python/tornado_test/ihome/config.py modified; restarting server
[I 171124 16:04:02 Passport:82] info
[W 171124 16:04:02 Passport:84] warnning
[E 171124 16:04:02 Passport:85] error
[E 171124 16:04:02 web:1590] Uncaught exception POST /api/login (127.0.0.1)
    HTTPServerRequest(protocol='http', host='127.0.0.1:8000', method='POST', uri='/api/login', version='HTTP/1.1', remote_ip='127.0.0.1', headers={'Content-Length': '30', 'Accept-Encoding': 'gzip, deflate', 'Connection': 'keep-alive', 'Accept': '*/*', 'User-Agent': 'PostmanRuntime/6.4.1', 'Host': '127.0.0.1:8000', 'Cookie': '_xsrf=2|f68f9254|41dd548a8fec66ca6cfaac5ebeed591b|1511509421', 'Cache-Control': 'no-cache', 'Content-Type': 'text/plain', 'Postman-Token': 'cdab3590-c4c3-4f53-91c9-ac6b4659dda2'})
    Traceback (most recent call last):
      File "/home/lianch/.local/lib/python2.7/site-packages/tornado/web.py", line 1509, in _execute
        result = method(*self.path_args, **self.path_kwargs)
      File "/home/lianch/myprojects/python/tornado_test/ihome/handlers/Passport.py", line 88, in post
        if not all((mobile,passwd)):
    UnboundLocalError: local variable 'passwd' referenced before assignment
[E 171124 16:04:02 web:2063] 500 POST /api/login (127.0.0.1) 3.40ms
[I 171124 16:04:36 autoreload:198] /home/lianch/myprojects/python/tornado_test/ihome/config.py modified; restarting server
[E 171124 16:04:47 Passport:85] error
[E 171124 16:04:47 web:1590] Uncaught exception POST /api/login (127.0.0.1)
    HTTPServerRequest(protocol='http', host='127.0.0.1:8000', method='POST', uri='/api/login', version='HTTP/1.1', remote_ip='127.0.0.1', headers={'Content-Length': '30', 'Accept-Encoding': 'gzip, deflate', 'Connection': 'keep-alive', 'Accept': '*/*', 'User-Agent': 'PostmanRuntime/6.4.1', 'Host': '127.0.0.1:8000', 'Cookie': '_xsrf=2|f68f9254|41dd548a8fec66ca6cfaac5ebeed591b|1511509421', 'Cache-Control': 'no-cache', 'Content-Type': 'text/plain', 'Postman-Token': 'd0081ce6-1c84-41b1-b338-e4a9c077bb72'})
    Traceback (most recent call last):
      File "/home/lianch/.local/lib/python2.7/site-packages/tornado/web.py", line 1509, in _execute
        result = method(*self.path_args, **self.path_kwargs)
      File "/home/lianch/myprojects/python/tornado_test/ihome/handlers/Passport.py", line 88, in post
        if not all((mobile,passwd)):
    UnboundLocalError: local variable 'passwd' referenced before assignment
[E 171124 16:04:47 web:2063] 500 POST /api/login (127.0.0.1) 2.85ms
[I 171124 16:05:06 autoreload:198] /home/lianch/myprojects/python/tornado_test/ihome/config.py modified; restarting server
[I 171124 16:05:24 autoreload:198] /home/lianch/myprojects/python/tornado_test/ihome/handlers/Passport.py modified; restarting server
[I 171124 16:07:14 autoreload:198] /home/lianch/myprojects/python/tornado_test/ihome/config.py modified; restarting server
[I 171124 16:13:23 autoreload:198] server.py modified; restarting server
[I 171124 18:15:34 autoreload:198] /home/lianch/myprojects/python/tornado_test/ihome/config.py modified; restarting server
[I 171124 18:15:44 autoreload:198] /home/lianch/myprojects/python/tornado_test/ihome/config.py modified; restarting server
[I 171124 18:20:43 autoreload:198] /home/lianch/myprojects/python/tornado_test/ihome/handlers/Passport.py modified; restarting server
[I 171124 18:24:14 web:2063] 200 POST /api/register (127.0.0.1) 0.81ms
[I 171124 18:26:04 web:2063] 200 POST /api/register (127.0.0.1) 0.62ms
[I 171124 18:27:16 web:2063] 200 POST /api/register (127.0.0.1) 0.51ms
[I 171124 18:28:33 autoreload:198] /home/lianch/myprojects/python/tornado_test/ihome/handlers/Passport.py modified; restarting server
[E 171124 18:28:42 web:1590] Uncaught exception POST /api/register (127.0.0.1)
    HTTPServerRequest(protocol='http', host='127.0.0.1:8000', method='POST', uri='/api/register', version='HTTP/1.1', remote_ip='127.0.0.1', headers={'Content-Length': '61', 'Accept-Encoding': 'gzip, deflate', 'Connection': 'keep-alive', 'Accept': '*/*', 'User-Agent': 'PostmanRuntime/6.4.1', 'Host': '127.0.0.1:8000', 'Cookie': '_xsrf=2|f68f9254|41dd548a8fec66ca6cfaac5ebeed591b|1511509421', 'Cache-Control': 'no-cache', 'Content-Type': 'text/plain', 'Postman-Token': 'bac12a32-92a1-4d64-98c8-f3a809a32612'})
    Traceback (most recent call last):
      File "/home/lianch/.local/lib/python2.7/site-packages/tornado/web.py", line 1509, in _execute
        result = method(*self.path_args, **self.path_kwargs)
      File "/home/lianch/myprojects/python/tornado_test/ihome/handlers/Passport.py", line 23, in post
        print 'json_args',json_args
    NameError: global name 'json_args' is not defined
[E 171124 18:28:42 web:2063] 500 POST /api/register (127.0.0.1) 3.73ms
[E 171124 18:29:06 web:1590] Uncaught exception POST /api/register (127.0.0.1)
    HTTPServerRequest(protocol='http', host='127.0.0.1:8000', method='POST', uri='/api/register', version='HTTP/1.1', remote_ip='127.0.0.1', headers={'Content-Length': '67', 'Accept-Encoding': 'gzip, deflate', 'Connection': 'keep-alive', 'Accept': '*/*', 'User-Agent': 'PostmanRuntime/6.4.1', 'Host': '127.0.0.1:8000', 'Cookie': '_xsrf=2|f68f9254|41dd548a8fec66ca6cfaac5ebeed591b|1511509421', 'Cache-Control': 'no-cache', 'Content-Type': 'text/plain', 'Postman-Token': '737d1661-e77f-4697-b9d1-8f693aafc0de'})
    Traceback (most recent call last):
      File "/home/lianch/.local/lib/python2.7/site-packages/tornado/web.py", line 1509, in _execute
        result = method(*self.path_args, **self.path_kwargs)
      File "/home/lianch/myprojects/python/tornado_test/ihome/handlers/Passport.py", line 23, in post
        print 'json_args',json_args
    NameError: global name 'json_args' is not defined
[E 171124 18:29:06 web:2063] 500 POST /api/register (127.0.0.1) 1.34ms
[I 171124 18:29:46 autoreload:198] /home/lianch/myprojects/python/tornado_test/ihome/handlers/Passport.py modified; restarting server
[I 171124 18:29:54 web:2063] 200 POST /api/register (127.0.0.1) 0.86ms
[E 171124 18:30:04 web:1590] Uncaught exception POST /api/register (127.0.0.1)
    HTTPServerRequest(protocol='http', host='127.0.0.1:8000', method='POST', uri='/api/register', version='HTTP/1.1', remote_ip='127.0.0.1', headers={'Content-Length': '67', 'Accept-Encoding': 'gzip, deflate', 'Connection': 'keep-alive', 'Accept': '*/*', 'User-Agent': 'PostmanRuntime/6.4.1', 'Host': '127.0.0.1:8000', 'Cookie': '_xsrf=2|f68f9254|41dd548a8fec66ca6cfaac5ebeed591b|1511509421', 'Cache-Control': 'no-cache', 'Content-Type': 'application/json', 'Postman-Token': 'f972303c-7a79-4c97-b200-538e7994c8da'})
    Traceback (most recent call last):
      File "/home/lianch/.local/lib/python2.7/site-packages/tornado/web.py", line 1488, in _execute
        result = self.prepare()
      File "/home/lianch/myprojects/python/tornado_test/ihome/handlers/BaseHandler.py", line 53, in prepare
        self.json_args = json.loads(self.request.body)
      File "/usr/lib/python2.7/json/__init__.py", line 339, in loads
        return _default_decoder.decode(s)
      File "/usr/lib/python2.7/json/decoder.py", line 364, in decode
        obj, end = self.raw_decode(s, idx=_w(s, 0).end())
      File "/usr/lib/python2.7/json/decoder.py", line 380, in raw_decode
        obj, end = self.scan_once(s, idx)
    ValueError: Expecting property name: line 2 column 1 (char 2)
[E 171124 18:30:04 web:2063] 500 POST /api/register (127.0.0.1) 18.83ms
[E 171124 18:30:51 web:1590] Uncaught exception POST /api/register (127.0.0.1)
    HTTPServerRequest(protocol='http', host='127.0.0.1:8000', method='POST', uri='/api/register', version='HTTP/1.1', remote_ip='127.0.0.1', headers={'Content-Length': '61', 'Accept-Encoding': 'gzip, deflate', 'Connection': 'keep-alive', 'Accept': '*/*', 'User-Agent': 'PostmanRuntime/6.4.1', 'Host': '127.0.0.1:8000', 'Cookie': '_xsrf=2|f68f9254|41dd548a8fec66ca6cfaac5ebeed591b|1511509421', 'Cache-Control': 'no-cache', 'Content-Type': 'application/json', 'Postman-Token': '6033e290-5b79-4529-a3e9-a5053d9d6196'})
    Traceback (most recent call last):
      File "/home/lianch/.local/lib/python2.7/site-packages/tornado/web.py", line 1488, in _execute
        result = self.prepare()
      File "/home/lianch/myprojects/python/tornado_test/ihome/handlers/BaseHandler.py", line 53, in prepare
        self.json_args = json.loads(self.request.body)
      File "/usr/lib/python2.7/json/__init__.py", line 339, in loads
        return _default_decoder.decode(s)
      File "/usr/lib/python2.7/json/decoder.py", line 364, in decode
        obj, end = self.raw_decode(s, idx=_w(s, 0).end())
      File "/usr/lib/python2.7/json/decoder.py", line 380, in raw_decode
        obj, end = self.scan_once(s, idx)
    ValueError: Expecting property name: line 2 column 1 (char 2)
[E 171124 18:30:51 web:2063] 500 POST /api/register (127.0.0.1) 1.18ms
[E 171124 18:35:48 web:1590] Uncaught exception POST /api/register (127.0.0.1)
    HTTPServerRequest(protocol='http', host='127.0.0.1:8000', method='POST', uri='/api/register', version='HTTP/1.1', remote_ip='127.0.0.1', headers={'Content-Length': '67', 'Accept-Encoding': 'gzip, deflate', 'Connection': 'keep-alive', 'Accept': '*/*', 'User-Agent': 'PostmanRuntime/6.4.1', 'Host': '127.0.0.1:8000', 'Cookie': '_xsrf=2|f68f9254|41dd548a8fec66ca6cfaac5ebeed591b|1511509421', 'Cache-Control': 'no-cache', 'Content-Type': 'application/json', 'Postman-Token': '2aa7f566-c00e-4aa9-b599-c6bebc7b865e'})
    Traceback (most recent call last):
      File "/home/lianch/.local/lib/python2.7/site-packages/tornado/web.py", line 1509, in _execute
        result = method(*self.path_args, **self.path_kwargs)
      File "/home/lianch/myprojects/python/tornado_test/ihome/handlers/Passport.py", line 67, in post
        session = Session(self)
      File "/home/lianch/myprojects/python/tornado_test/ihome/utils/session.py", line 16, in __init__
        self.session_id = request_handler_obj.get_secure_cookie("session_id")
      File "/home/lianch/.local/lib/python2.7/site-packages/tornado/web.py", line 656, in get_secure_cookie
        self.require_setting("cookie_secret", "secure cookies")
      File "/home/lianch/.local/lib/python2.7/site-packages/tornado/web.py", line 1390, in require_setting
        "application to use %s" % (name, feature))
    Exception: You must define the 'cookie_secret' setting in your application to use secure cookies
[E 171124 18:35:48 web:2063] 500 POST /api/register (127.0.0.1) 48.26ms
[E 171124 18:36:28 Passport:63] (1062, "Duplicate entry '12311111111' for key 'up_name'")
[I 171124 18:36:28 web:2063] 200 POST /api/register (127.0.0.1) 37.78ms
[E 171124 18:36:48 web:1590] Uncaught exception POST /api/register (127.0.0.1)
    HTTPServerRequest(protocol='http', host='127.0.0.1:8000', method='POST', uri='/api/register', version='HTTP/1.1', remote_ip='127.0.0.1', headers={'Content-Length': '67', 'Accept-Encoding': 'gzip, deflate', 'Connection': 'keep-alive', 'Accept': '*/*', 'User-Agent': 'PostmanRuntime/6.4.1', 'Host': '127.0.0.1:8000', 'Cache-Control': 'no-cache', 'Content-Type': 'application/json', 'Postman-Token': '501577b3-3013-4bd0-89b6-273b4ccf26b5'})
    Traceback (most recent call last):
      File "/home/lianch/.local/lib/python2.7/site-packages/tornado/web.py", line 1509, in _execute
        result = method(*self.path_args, **self.path_kwargs)
      File "/home/lianch/myprojects/python/tornado_test/ihome/handlers/Passport.py", line 67, in post
        session = Session(self)
      File "/home/lianch/myprojects/python/tornado_test/ihome/utils/session.py", line 16, in __init__
        self.session_id = request_handler_obj.get_secure_cookie("session_id")
      File "/home/lianch/.local/lib/python2.7/site-packages/tornado/web.py", line 656, in get_secure_cookie
        self.require_setting("cookie_secret", "secure cookies")
      File "/home/lianch/.local/lib/python2.7/site-packages/tornado/web.py", line 1390, in require_setting
        "application to use %s" % (name, feature))
    Exception: You must define the 'cookie_secret' setting in your application to use secure cookies
[E 171124 18:36:48 web:2063] 500 POST /api/register (127.0.0.1) 38.24ms
[I 171124 18:37:33 autoreload:198] /home/lianch/myprojects/python/tornado_test/ihome/config.py modified; restarting server
[W 171124 18:37:46 web:1587] 403 POST /api/register (127.0.0.1): '_xsrf' argument missing from POST
[W 171124 18:37:46 web:2063] 403 POST /api/register (127.0.0.1) 2.16ms
[W 171124 18:38:34 web:1587] 403 POST /api/register (127.0.0.1): '_xsrf' argument missing from POST
[W 171124 18:38:34 web:2063] 403 POST /api/register (127.0.0.1) 1.43ms
[I 171124 18:39:42 web:2063] 200 GET / (127.0.0.1) 6.99ms
[W 171124 18:39:55 web:1587] 403 POST /api/login (127.0.0.1): '_xsrf' argument missing from POST
[W 171124 18:39:55 web:2063] 403 POST /api/login (127.0.0.1) 1.01ms
[W 171124 18:40:18 web:1587] 403 POST /api/register (127.0.0.1): '_xsrf' argument missing from POST
[W 171124 18:40:18 web:2063] 403 POST /api/register (127.0.0.1) 0.77ms
[W 171124 18:41:07 web:1587] 403 POST /api/register (127.0.0.1): '_xsrf' argument missing from POST
[W 171124 18:41:07 web:2063] 403 POST /api/register (127.0.0.1) 0.91ms
[W 171124 18:42:11 web:1587] 403 POST /api/register (127.0.0.1): '_xsrf' argument missing from POST
[W 171124 18:42:11 web:2063] 403 POST /api/register (127.0.0.1) 1.40ms
[W 171124 18:42:40 web:1587] 403 POST /api/register (127.0.0.1): '_xsrf' argument missing from POST
[W 171124 18:42:40 web:2063] 403 POST /api/register (127.0.0.1) 0.99ms
[W 171124 18:43:01 web:1587] 403 POST /api/register (127.0.0.1): '_xsrf' argument missing from POST
[W 171124 18:43:01 web:2063] 403 POST /api/register (127.0.0.1) 1.09ms
[W 171124 18:44:35 web:1587] 403 POST /api/register (127.0.0.1): '_xsrf' argument missing from POST
[W 171124 18:44:35 web:2063] 403 POST /api/register (127.0.0.1) 0.84ms
[W 171124 18:45:17 web:1587] 403 POST /api/register (127.0.0.1): '_xsrf' argument missing from POST
[W 171124 18:45:17 web:2063] 403 POST /api/register (127.0.0.1) 1.02ms
[I 171124 18:46:19 autoreload:198] /home/lianch/myprojects/python/tornado_test/ihome/config.py modified; restarting server
[E 171124 18:46:31 web:1590] Uncaught exception POST /api/register (127.0.0.1)
    HTTPServerRequest(protocol='http', host='127.0.0.1:8000', method='POST', uri='/api/register', version='HTTP/1.1', remote_ip='127.0.0.1', headers={'Content-Length': '69', 'Accept-Encoding': 'gzip, deflate', 'Host': '127.0.0.1:8000', 'Accept': '*/*', 'User-Agent': 'PostmanRuntime/6.4.1', '_xsrf': '[{"key":"","value":"2|46a33ba5|9770048c4493bfb63787959376999eba|1511519982","description":""}]', 'Connection': 'keep-alive', 'Cookie': '_xsrf=2|46a33ba5|9770048c4493bfb63787959376999eba|1511519982', 'Cache-Control': 'no-cache', 'Content-Type': 'application/json', 'Postman-Token': '720fcfeb-c1e8-4a6b-8030-20040a2b3332'})
    Traceback (most recent call last):
      File "/home/lianch/.local/lib/python2.7/site-packages/tornado/web.py", line 1488, in _execute
        result = self.prepare()
      File "/home/lianch/myprojects/python/tornado_test/ihome/handlers/BaseHandler.py", line 53, in prepare
        self.json_args = json.loads(self.request.body)
      File "/usr/lib/python2.7/json/__init__.py", line 339, in loads
        return _default_decoder.decode(s)
      File "/usr/lib/python2.7/json/decoder.py", line 364, in decode
        obj, end = self.raw_decode(s, idx=_w(s, 0).end())
      File "/usr/lib/python2.7/json/decoder.py", line 380, in raw_decode
        obj, end = self.scan_once(s, idx)
    ValueError: Expecting property name: line 6 column 1 (char 68)
[E 171124 18:46:31 web:2063] 500 POST /api/register (127.0.0.1) 2.31ms
[E 171124 18:47:02 web:1590] Uncaught exception POST /api/register (127.0.0.1)
    HTTPServerRequest(protocol='http', host='127.0.0.1:8000', method='POST', uri='/api/register', version='HTTP/1.1', remote_ip='127.0.0.1', headers={'Content-Length': '68', 'Accept-Encoding': 'gzip, deflate', 'Host': '127.0.0.1:8000', 'Accept': '*/*', 'User-Agent': 'PostmanRuntime/6.4.1', '_xsrf': '[{"key":"","value":"2|46a33ba5|9770048c4493bfb63787959376999eba|1511519982","description":""}]', 'Connection': 'keep-alive', 'Cookie': '_xsrf=2|46a33ba5|9770048c4493bfb63787959376999eba|1511519982', 'Cache-Control': 'no-cache', 'Content-Type': 'application/json', 'Postman-Token': '7e6c615c-fed6-4f51-9601-a28bfaa79e69'})
    Traceback (most recent call last):
      File "/home/lianch/.local/lib/python2.7/site-packages/tornado/web.py", line 1488, in _execute
        result = self.prepare()
      File "/home/lianch/myprojects/python/tornado_test/ihome/handlers/BaseHandler.py", line 53, in prepare
        self.json_args = json.loads(self.request.body)
      File "/usr/lib/python2.7/json/__init__.py", line 339, in loads
        return _default_decoder.decode(s)
      File "/usr/lib/python2.7/json/decoder.py", line 364, in decode
        obj, end = self.raw_decode(s, idx=_w(s, 0).end())
      File "/usr/lib/python2.7/json/decoder.py", line 380, in raw_decode
        obj, end = self.scan_once(s, idx)
    ValueError: Expecting property name: line 5 column 1 (char 67)
[E 171124 18:47:02 web:2063] 500 POST /api/register (127.0.0.1) 1.40ms
[E 171124 18:47:16 web:1590] Uncaught exception POST /api/register (127.0.0.1)
    HTTPServerRequest(protocol='http', host='127.0.0.1:8000', method='POST', uri='/api/register', version='HTTP/1.1', remote_ip='127.0.0.1', headers={'Content-Length': '68', 'Accept-Encoding': 'gzip, deflate', 'Connection': 'keep-alive', 'Accept': '*/*', 'User-Agent': 'PostmanRuntime/6.4.1', 'Host': '127.0.0.1:8000', 'Cookie': '_xsrf=2|46a33ba5|9770048c4493bfb63787959376999eba|1511519982', 'Cache-Control': 'no-cache', 'Content-Type': 'application/json', 'Postman-Token': '5a3e5927-b96d-43d8-98e3-6d786d1caedf'})
    Traceback (most recent call last):
      File "/home/lianch/.local/lib/python2.7/site-packages/tornado/web.py", line 1488, in _execute
        result = self.prepare()
      File "/home/lianch/myprojects/python/tornado_test/ihome/handlers/BaseHandler.py", line 53, in prepare
        self.json_args = json.loads(self.request.body)
      File "/usr/lib/python2.7/json/__init__.py", line 339, in loads
        return _default_decoder.decode(s)
      File "/usr/lib/python2.7/json/decoder.py", line 364, in decode
        obj, end = self.raw_decode(s, idx=_w(s, 0).end())
      File "/usr/lib/python2.7/json/decoder.py", line 380, in raw_decode
        obj, end = self.scan_once(s, idx)
    ValueError: Expecting property name: line 5 column 1 (char 67)
[E 171124 18:47:16 web:2063] 500 POST /api/register (127.0.0.1) 1.12ms
[I 171124 18:47:45 autoreload:198] /home/lianch/myprojects/python/tornado_test/ihome/config.py modified; restarting server
[E 171124 18:48:03 web:1590] Uncaught exception POST /api/register (127.0.0.1)
    HTTPServerRequest(protocol='http', host='127.0.0.1:8000', method='POST', uri='/api/register', version='HTTP/1.1', remote_ip='127.0.0.1', headers={'Content-Length': '65', 'Accept-Encoding': 'gzip, deflate', 'Connection': 'keep-alive', 'Accept': '*/*', 'User-Agent': 'PostmanRuntime/6.4.1', 'Host': '127.0.0.1:8000', 'Cookie': '_xsrf=2|46a33ba5|9770048c4493bfb63787959376999eba|1511519982', 'Cache-Control': 'no-cache', 'Content-Type': 'application/json', 'Postman-Token': 'aea253ef-9df2-450b-b095-ac0c1a8ff86e'})
    Traceback (most recent call last):
      File "/home/lianch/.local/lib/python2.7/site-packages/tornado/web.py", line 1488, in _execute
        result = self.prepare()
      File "/home/lianch/myprojects/python/tornado_test/ihome/handlers/BaseHandler.py", line 53, in prepare
        self.json_args = json.loads(self.request.body)
      File "/usr/lib/python2.7/json/__init__.py", line 339, in loads
        return _default_decoder.decode(s)
      File "/usr/lib/python2.7/json/decoder.py", line 364, in decode
        obj, end = self.raw_decode(s, idx=_w(s, 0).end())
      File "/usr/lib/python2.7/json/decoder.py", line 380, in raw_decode
        obj, end = self.scan_once(s, idx)
    ValueError: Expecting object: line 4 column 19 (char 64)
[E 171124 18:48:03 web:2063] 500 POST /api/register (127.0.0.1) 2.19ms
[E 171124 18:48:06 web:1590] Uncaught exception POST /api/register (127.0.0.1)
    HTTPServerRequest(protocol='http', host='127.0.0.1:8000', method='POST', uri='/api/register', version='HTTP/1.1', remote_ip='127.0.0.1', headers={'Content-Length': '65', 'Accept-Encoding': 'gzip, deflate', 'Connection': 'keep-alive', 'Accept': '*/*', 'User-Agent': 'PostmanRuntime/6.4.1', 'Host': '127.0.0.1:8000', 'Cookie': '_xsrf=2|46a33ba5|9770048c4493bfb63787959376999eba|1511519982', 'Cache-Control': 'no-cache', 'Content-Type': 'application/json', 'Postman-Token': 'd323c786-1a3b-4a56-8e44-599b1a0f2caa'})
    Traceback (most recent call last):
      File "/home/lianch/.local/lib/python2.7/site-packages/tornado/web.py", line 1488, in _execute
        result = self.prepare()
      File "/home/lianch/myprojects/python/tornado_test/ihome/handlers/BaseHandler.py", line 53, in prepare
        self.json_args = json.loads(self.request.body)
      File "/usr/lib/python2.7/json/__init__.py", line 339, in loads
        return _default_decoder.decode(s)
      File "/usr/lib/python2.7/json/decoder.py", line 364, in decode
        obj, end = self.raw_decode(s, idx=_w(s, 0).end())
      File "/usr/lib/python2.7/json/decoder.py", line 380, in raw_decode
        obj, end = self.scan_once(s, idx)
    ValueError: Expecting object: line 4 column 19 (char 64)
[E 171124 18:48:06 web:2063] 500 POST /api/register (127.0.0.1) 1.48ms
[E 171124 18:48:12 web:1590] Uncaught exception POST /api/register (127.0.0.1)
    HTTPServerRequest(protocol='http', host='127.0.0.1:8000', method='POST', uri='/api/register', version='HTTP/1.1', remote_ip='127.0.0.1', headers={'Content-Length': '67', 'Accept-Encoding': 'gzip, deflate', 'Connection': 'keep-alive', 'Accept': '*/*', 'User-Agent': 'PostmanRuntime/6.4.1', 'Host': '127.0.0.1:8000', 'Cookie': '_xsrf=2|46a33ba5|9770048c4493bfb63787959376999eba|1511519982', 'Cache-Control': 'no-cache', 'Content-Type': 'application/json', 'Postman-Token': '7c5e1143-c977-429f-aabb-bdda53446b5f'})
    Traceback (most recent call last):
      File "/home/lianch/.local/lib/python2.7/site-packages/tornado/web.py", line 1509, in _execute
        result = method(*self.path_args, **self.path_kwargs)
      File "/home/lianch/myprojects/python/tornado_test/ihome/handlers/Passport.py", line 67, in post
        session = Session(self)
      File "/home/lianch/myprojects/python/tornado_test/ihome/utils/session.py", line 16, in __init__
        self.session_id = request_handler_obj.get_secure_cookie("session_id")
      File "/home/lianch/.local/lib/python2.7/site-packages/tornado/web.py", line 656, in get_secure_cookie
        self.require_setting("cookie_secret", "secure cookies")
      File "/home/lianch/.local/lib/python2.7/site-packages/tornado/web.py", line 1390, in require_setting
        "application to use %s" % (name, feature))
    Exception: You must define the 'cookie_secret' setting in your application to use secure cookies
[E 171124 18:48:12 web:2063] 500 POST /api/register (127.0.0.1) 135.15ms
[E 171124 18:50:28 web:1590] Uncaught exception POST /api/login (127.0.0.1)
    HTTPServerRequest(protocol='http', host='127.0.0.1:8000', method='POST', uri='/api/login', version='HTTP/1.1', remote_ip='127.0.0.1', headers={'Content-Length': '67', 'Accept-Encoding': 'gzip, deflate', 'Connection': 'keep-alive', 'Accept': '*/*', 'User-Agent': 'PostmanRuntime/6.4.1', 'Host': '127.0.0.1:8000', 'Cookie': '_xsrf=2|46a33ba5|9770048c4493bfb63787959376999eba|1511519982', 'Cache-Control': 'no-cache', 'Content-Type': 'application/json', 'Postman-Token': 'd052c359-41b7-4e6e-864d-35dd7f66b06c'})
    Traceback (most recent call last):
      File "/home/lianch/.local/lib/python2.7/site-packages/tornado/web.py", line 1509, in _execute
        result = method(*self.path_args, **self.path_kwargs)
      File "/home/lianch/myprojects/python/tornado_test/ihome/handlers/Passport.py", line 88, in post
        if not all((mobile,passwd)):
    UnboundLocalError: local variable 'passwd' referenced before assignment
[E 171124 18:50:28 web:2063] 500 POST /api/login (127.0.0.1) 0.99ms
[I 171124 18:51:37 autoreload:198] /home/lianch/myprojects/python/tornado_test/ihome/handlers/Passport.py modified; restarting server
[E 171124 18:51:39 web:1590] Uncaught exception POST /api/login (127.0.0.1)
    HTTPServerRequest(protocol='http', host='127.0.0.1:8000', method='POST', uri='/api/login', version='HTTP/1.1', remote_ip='127.0.0.1', headers={'Content-Length': '67', 'Accept-Encoding': 'gzip, deflate', 'Connection': 'keep-alive', 'Accept': '*/*', 'User-Agent': 'PostmanRuntime/6.4.1', 'Host': '127.0.0.1:8000', 'Cookie': '_xsrf=2|46a33ba5|9770048c4493bfb63787959376999eba|1511519982', 'Cache-Control': 'no-cache', 'Content-Type': 'application/json', 'Postman-Token': '402fb2af-0720-4dae-aed6-814892f23f26'})
    Traceback (most recent call last):
      File "/home/lianch/.local/lib/python2.7/site-packages/tornado/web.py", line 1509, in _execute
        result = method(*self.path_args, **self.path_kwargs)
      File "/home/lianch/myprojects/python/tornado_test/ihome/handlers/Passport.py", line 91, in post
        return self.write(ditc(errcode=RET.DATAERR,errmsg='手机好错误'))
    NameError: global name 'ditc' is not defined
[E 171124 18:51:39 web:2063] 500 POST /api/login (127.0.0.1) 2.76ms
[I 171124 18:52:37 autoreload:198] /home/lianch/myprojects/python/tornado_test/ihome/handlers/Passport.py modified; restarting server
[I 171124 18:52:39 web:2063] 200 POST /api/login (127.0.0.1) 2.07ms
[I 171124 18:53:29 autoreload:198] /home/lianch/myprojects/python/tornado_test/ihome/handlers/Passport.py modified; restarting server
[E 171124 18:53:32 Passport:107] You must define the 'cookie_secret' setting in your application to use secure cookies
[I 171124 18:53:32 web:2063] 200 POST /api/login (127.0.0.1) 3.20ms
[I 171124 18:53:52 autoreload:198] /home/lianch/myprojects/python/tornado_test/ihome/handlers/Passport.py modified; restarting server
[I 171124 18:54:09 autoreload:198] /home/lianch/myprojects/python/tornado_test/ihome/handlers/Passport.py modified; restarting server
